<?xml version="1.0" encoding="utf-8"?>
<!-- This URDF was automatically created by SolidWorks to URDF Exporter! Originally created by Stephen Brawner (brawner@gmail.com) 
     Commit Version: 1.6.0-4-g7f85cfe  Build Version: 1.6.7995.38578
     For more information, please see http://wiki.ros.org/sw_urdf_exporter -->

<!-- The collision geometry of the paw is inclued in the inner shank collision geometry -->
<robot
  name="olympus_description">

  <!-- Materials -->
  <material name="housing_material">
    <color rgba="0.9451    0.6000    0.1765 1"/>
  </material>
  <material name="hip_material">
    <color rgba="0.7490    0.3020    0.3020 1"/>
  </material>
  <material name="shank_material">
    <color rgba="0.3412    0.4275    0.8275 1"/>
  </material>
  <material name="body_material">
    <color rgba="0.5294    0.5020    0.4745 1"/>
  </material>


  <link name="world"/>
  
  <link name="Body">
    <inertial>
      <origin
        xyz="-0.0093903 0.00018696 0.011109"
        rpy="0 0 0" />
      <!-- <mass
        value="8.5185" />
      <inertia
        ixx="0.081429225"
        ixy="-0.001652685"
        ixz="-0.0025551"
        iyy="0.22605897"
        iyz="0.000203775"
        izz="0.29362083" /> -->
      <mass
        value="5.679" />
      <inertia
        ixx="0.05428615"
        ixy="-0.00110179"
        ixz="-0.0017034"
        iyy="0.15070598"
        iyz="0.00013585"
        izz="0.19574722" />
    </inertial>

    <visual name="main_body">
      <origin
        xyz="0 0 0"
        rpy="0 0 0" />
      <geometry>
        <mesh
          filename="meshes/visual_meshes/body/main_body.obj" />
      </geometry>
      <material
        name="body_material">
      </material>
    </visual>
    <visual name="main_body_lower">
      <origin
        xyz="0 0 0"
        rpy="0 0 0" />
      <geometry>
        <mesh
          filename="meshes/visual_meshes/body/main_body_lower.obj" />
      </geometry>
      <material
        name="body_material">
      </material>
    </visual>
    <visual name="main_body_upper">
      <origin
        xyz="0 0 0"
        rpy="0 0 0" />
      <geometry>
        <mesh
          filename="meshes/visual_meshes/body/main_body_upper.obj" />
      </geometry>
      <material
        name="body_material">
      </material>
    </visual>
    <visual name="front_body">
      <origin
        xyz="0 0 0"
        rpy="0 0 0" />
      <geometry>
        <mesh
          filename="meshes/visual_meshes/body/front_body.obj" />
      </geometry>
      <material
        name="body_material">
      </material>
    </visual>
    <visual name="front_cover_upper">
      <origin
        xyz="0 0 0"
        rpy="0 0 0" />
      <geometry>
        <mesh
          filename="meshes/visual_meshes/body/front_cover_upper.obj" />
      </geometry>
      <material
        name="body_material">
      </material>
    </visual>
    <visual name="front_cover_lower">
      <origin
        xyz="0 0 0"
        rpy="0 0 0" />
      <geometry>
        <mesh
          filename="meshes/visual_meshes/body/front_cover_lower.obj" />
      </geometry>
      <material
        name="body_material">
      </material>
    </visual>
    <visual name="front_cover_lower_2">
      <origin
        xyz="0 0 0"
        rpy="0 0 0" />
      <geometry>
        <mesh
          filename="meshes/visual_meshes/body/front_cover_lower_2.obj" />
      </geometry>
      <material
        name="body_material">
      </material>
    </visual>
    <visual name="front_motors">
      <origin
        xyz="0 0 0"
        rpy="0 0 0" />
      <geometry>
        <mesh
          filename="meshes/visual_meshes/body/front_motors.obj" />
      </geometry>
      <material
        name="body_material">
      </material>
    </visual>
    <visual name="rear_body_upper">
      <origin
        xyz="0 0 0"
        rpy="0 0 0" />
      <geometry>
        <mesh
          filename="meshes/visual_meshes/body/rear_body_upper.obj" />
      </geometry>
      <material
        name="body_material">
      </material>
    </visual>
    <visual name="rear_body_lower">
      <origin
        xyz="0 0 0"
        rpy="0 0 0" />
      <geometry>
        <mesh
          filename="meshes/visual_meshes/body/rear_body_lower.obj" />
      </geometry>
      <material
        name="body_material">
      </material>
    </visual>
    <visual name="rear_cover_upper">
      <origin
        xyz="0 0 0"
        rpy="0 0 0" />
      <geometry>
        <mesh
          filename="meshes/visual_meshes/body/rear_cover_upper.obj" />
      </geometry>
      <material
        name="body_material">
      </material>
    </visual>
    <visual name="rear_cover_lower">
      <origin
        xyz="0 0 0"
        rpy="0 0 0" />
      <geometry>
        <mesh
          filename="meshes/visual_meshes/body/rear_cover_lower.obj" />
      </geometry>
      <material
        name="body_material">
      </material>
    </visual>
    <visual name="rear_motors">
      <origin
        xyz="0 0 0"
        rpy="0 0 0" />
      <geometry>
        <mesh
          filename="meshes/visual_meshes/body/rear_motors.obj" />
      </geometry>
      <material
        name="body_material">
      </material>
    </visual>

    <collision name="main_body">
      <origin
        xyz="0 0 0"
        rpy="0 0 0" />
      <geometry>
        <mesh
          filename="meshes/collision_meshes/body/main_body.obj" />
      </geometry>
    </collision>
    <collision name="main_body_lower">
      <origin
        xyz="0 0 0"
        rpy="0 0 0" />
      <geometry>
        <mesh
          filename="meshes/collision_meshes/body/main_body_lower.obj" />
      </geometry>
    </collision>
    <collision name="main_body_upper">
      <origin
        xyz="0 0 0"
        rpy="0 0 0" />
      <geometry>
        <mesh
          filename="meshes/collision_meshes/body/main_body_upper.obj" />
      </geometry>
    </collision>
    <collision name="front_body">
      <origin
        xyz="0 0 0"
        rpy="0 0 0" />
      <geometry>
        <mesh
          filename="meshes/collision_meshes/body/front_body.obj" />
      </geometry>
    </collision>
    <collision name="front_cover_upper">
      <origin
        xyz="0 0 0"
        rpy="0 0 0" />
      <geometry>
        <mesh
          filename="meshes/collision_meshes/body/front_cover_upper.obj" />
      </geometry>
    </collision>
    <collision name="front_cover_lower">
      <origin
        xyz="0 0 0"
        rpy="0 0 0" />
      <geometry>
        <mesh
          filename="meshes/collision_meshes/body/front_cover_lower.obj" />
      </geometry>
    </collision>
    <collision name="front_cover_lower_2">
      <origin
        xyz="0 0 0"
        rpy="0 0 0" />
      <geometry>
        <mesh
          filename="meshes/collision_meshes/body/front_cover_lower_2.obj" />
      </geometry>
    </collision>
    <collision name="front_motors">
      <origin
        xyz="0 0 0"
        rpy="0 0 0" />
      <geometry>
        <mesh
          filename="meshes/collision_meshes/body/front_motors.obj" />
      </geometry>
    </collision>
    <collision name="rear_body_upper">
      <origin
        xyz="0 0 0"
        rpy="0 0 0" />
      <geometry>
        <mesh
          filename="meshes/collision_meshes/body/rear_body_upper.obj" />
      </geometry>
    </collision>
    <collision name="rear_body_lower">
      <origin
        xyz="0 0 0"
        rpy="0 0 0" />
      <geometry>
        <mesh
          filename="meshes/collision_meshes/body/rear_body_lower.obj" />
      </geometry>
    </collision>
    <collision name="rear_cover_upper">
      <origin
        xyz="0 0 0"
        rpy="0 0 0" />
      <geometry>
        <mesh
          filename="meshes/collision_meshes/body/rear_cover_upper.obj" />
      </geometry>
    </collision>
    <collision name="rear_cover_lower">
      <origin
        xyz="0 0 0"
        rpy="0 0 0" />
      <geometry>
        <mesh
          filename="meshes/collision_meshes/body/rear_cover_lower.obj" />
      </geometry>
    </collision>
    <collision name="rear_motors">
      <origin
        xyz="0 0 0"
        rpy="0 0 0" />
      <geometry>
        <mesh
          filename="meshes/collision_meshes/body/rear_motors.obj" />
      </geometry>
    </collision>
  </link>
  
  <!-- <joint name="world_joint" type="fixed" >
    <origin
          xyz="0 0 1"
          rpy="0 0 0" />
      <parent
        link="world" />
      <child
        link="Body" />
    <dynamics damping="0.0025" />
  </joint> -->
  
  <!-- Front Left Leg: -->
  <link name="FrontLeft_motorHousing">
    <inertial>
      <origin
        xyz="0.092829 0.02913 0.00023828"
        rpy="0 0 0" />
      <mass
        value="1.437" />
      <inertia
        ixx="0.00232895"
        ixy="0.00418147"
        ixz="3.194E-05"
        iyy="0.01861991"
        iyz="4.4E-06"
        izz="0.01948836" />
    </inertial>
    <visual name="MH_visual">
      <origin
        xyz="0.005 0 0"
        rpy="1.5708 0 0" />
      <geometry>
        <mesh
          filename="meshes/visual_meshes/leg/MH_visual.obj"/>
      </geometry>
      <material
        name="housing_material">
      </material>
    </visual>

    <collision name="MH_collision">
      <origin
        xyz="0.005 0 0"
        rpy="1.5708 0 0" />
      <geometry>
        <mesh
          filename="meshes/collision_meshes/leg/MH_collision.obj"/>
      </geometry>
    </collision>
  </link>
  <joint
    name="FrontLeft_motorHousing_hipAduction_motor3"
    type="revolute">
    <origin
      xyz="0.143300000000002 0.104999999999997 0"
      rpy="0 0 0" />
    <parent
      link="Body" />
    <child
      link="FrontLeft_motorHousing" />
    <axis
      xyz="-1 0 0" />
    <limit
      lower="-3.1416"
      upper="1.57"
      effort="0"
      velocity="0" />
    <dynamics damping="0.0025" />
  </joint>
  <link name="FrontLeft_hip_outer">
    <inertial>
      <origin
        xyz="0.00087097 -0.0026333 -0.059284"
        rpy="0 0 0" />
      <mass
        value="0.0813" />
      <inertia
        ixx="0.00080451"
        ixy="7E-08"
        ixz="-1.097E-05"
        iyy="0.00081035"
        iyz="-4.68E-06"
        izz="8.51E-06" />
    </inertial>
    <visual name="outerHip_long_visual">
      <origin
        xyz="0 0 0"
        rpy="0 0 0" />
      <geometry>
        <mesh
          filename="meshes/visual_meshes/leg/outerHip_long_visual.obj"/>
      </geometry>
      <material
        name="hip_material">
      </material>
    </visual>
    <visual name="outerHip_shank_visual">
      <origin
        xyz="0 0 0"
        rpy="0 0 0" />
      <geometry>
        <mesh
          filename="meshes/visual_meshes/leg/outerHip_shank_visual.obj"/>
      </geometry>
      <material
        name="hip_material">
      </material>
    </visual>

    <collision name="outerHip_long_collision">
      <origin
        xyz="0 0 0"
        rpy="0 0 0" />
      <geometry>
        <mesh
          filename="meshes/collision_meshes/leg/outerHip_long_collision.obj"/>
      </geometry>
    </collision>
    <collision name="outerHip_shank_collision">
      <origin
        xyz="0 0 0"
        rpy="0 0 0" />
      <geometry>
        <mesh
          filename="meshes/collision_meshes/leg/outerHip_shank_collision.obj"/>
      </geometry>
    </collision>
  </link>
  <joint
    name="FrontLeft_hip_outer_motor1"
    type="revolute">
    <origin
      xyz="0.141699999999999 0.0594499999999993 -1.13383701894222E-05"
      rpy="0 0 0" />
    <parent
      link="FrontLeft_motorHousing" />
    <child
      link="FrontLeft_hip_outer" />
    <axis
      xyz="0 -1 0" />
    <limit
      lower="-1.2040"
      upper="3.8776"
      effort="0"
      velocity="0" />
    <dynamics damping="0.0025" />
  </joint>
  <link name="FrontLeft_shank_outer">
    <inertial>
      <origin
        xyz="0.0044745 -6.207E-07 -0.16466"
        rpy="0 0 0" />
      <mass
        value="0.1992" />
      <inertia
        ixx="0.0081046"
        ixy="3E-08"
        ixz="-8.7E-05"
        iyy="0.00810896"
        iyz="-1.7E-06"
        izz="2.321E-05" />
    </inertial>
    <visual name="outerShank_joint_visual">
      <origin
        xyz="0 0 0"
        rpy="1.5708 1.5708 0" />
      <geometry>
        <mesh
          filename="meshes/visual_meshes/leg/outerShank_joint_visual.obj"/>
      </geometry>
      <material
        name="shank_material">
      </material>
    </visual>
    <visual name="outerShank_rod_visual">
      <origin
        xyz="0 0 0"
        rpy="1.5708 1.5708 0" />
      <geometry>
        <mesh
          filename="meshes/visual_meshes/leg/outerShank_rod_visual.obj"/>
      </geometry>
      <material
        name="shank_material">
      </material>
    </visual>
    <visual name="outerShank_paw_visual">
      <origin
        xyz="0 0 0"
        rpy="1.5708 1.5708 0" />
      <geometry>
        <mesh
          filename="meshes/visual_meshes/leg/outerShank_paw_visual.obj"/>
      </geometry>
      <material
        name="shank_material">
      </material>
    </visual>

    <collision name="outerShank_joint_collision">
      <origin
        xyz="0 0 0"
        rpy="1.5708 1.5708 0" />
      <geometry>
        <mesh
          filename="meshes/collision_meshes/leg/outerShank_joint_collision.obj"/>
      </geometry>
    </collision>
    <collision name="outerShank_rod_collision">
      <origin
        xyz="0 0 0"
        rpy="1.5708 1.5708 0" />
      <geometry>
        <mesh
          filename="meshes/collision_meshes/leg/outerShank_rod_collision.obj"/>
      </geometry>
    </collision>
    <collision name="outerShank_paw_collision">
      <origin
        xyz="0 0 0"
        rpy="1.5708 1.5708 0" />
      <geometry>
        <mesh
          filename="meshes/collision_meshes/leg/outerShank_paw_collision.obj"/>
      </geometry>
    </collision>
  </link>
  <joint
    name="FrontLeft_shank_outer_knee"
    type="revolute">
    <origin
      xyz="0 0.000749999999999196 -0.175000000000029"
      rpy="0 0.145529485228563 0" />
    <parent
      link="FrontLeft_hip_outer" />
    <child
      link="FrontLeft_shank_outer" />
    <axis
      xyz="0 1 0" />
    <limit
      lower="-1.2222"
      upper="2.6878"
      effort="0"
      velocity="0" />
    <dynamics damping="0.0025" />
  </joint>
  <link name="FrontLeft_hip_inner">
    <inertial>
      <origin
        xyz="-0.00087111 -0.0026375 -0.059532"
        rpy="0 0 0" />
      <mass
        value="0.081" />
      <inertia
        ixx="0.00080451"
        ixy="7E-08"
        ixz="-1.097E-05"
        iyy="0.00081035"
        iyz="-4.68E-06"
        izz="8.51E-06" />
    </inertial>
    <visual name="innerHip_long_visual">
      <origin
        xyz="0 0 0"
        rpy="0 0 0" />
      <geometry>
        <mesh
          filename="meshes/visual_meshes/leg/innerHip_long_visual.obj"/>
      </geometry>
      <material
        name="hip_material">
      </material>
    </visual>
    <visual name="innerHip_shank_visual">
      <origin
        xyz="0 0 0"
        rpy="0 0 0" />
      <geometry>
        <mesh
          filename="meshes/visual_meshes/leg/innerHip_shank_visual.obj"/>
      </geometry>
      <material
        name="hip_material">
      </material>
    </visual>

    <collision name="innerHip_long_collision">
      <origin
        xyz="0 0 0"
        rpy="0 0 0" />
      <geometry>
        <mesh
          filename="meshes/collision_meshes/leg/innerHip_long_collision.obj"/>
      </geometry>
    </collision>
    <collision name="innerHip_shank_collision">
      <origin
        xyz="0 0 0"
        rpy="0 0 0" />
      <geometry>
        <mesh
          filename="meshes/collision_meshes/leg/innerHip_shank_collision.obj"/>
      </geometry>
    </collision>
  </link>
  <joint
    name="FrontLeft_hip_inner_motor2"
    type="revolute">
    <origin
      xyz="0.051699999999999 0.0594499999999993 -1.1338370204463E-05"
      rpy="0 0 0" />
    <parent
      link="FrontLeft_motorHousing" />
    <child
      link="FrontLeft_hip_inner" />
    <axis
      xyz="0 -1 0" />
    <limit
      lower="-3.8803"
      upper="1.2013"
      effort="0"
      velocity="0" />
    <dynamics damping="0.0025" />
  </joint>
  <link name="FrontLeft_shank_inner">
    <inertial>
      <origin
        xyz="-0.018257 -5.7848E-07 -0.18193"
        rpy="0 0 0" />
      <mass
        value="0.1993" />
      <inertia
        ixx="0.00799515"
        ixy="-1.3E-07"
        ixz="0.00072855"
        iyy="0.00807089"
        iyz="-1.55E-06"
        izz="9.64E-05" />
    </inertial>
    <visual name="innerShank_joint_visual">
      <origin
        xyz="0 0 0"
        rpy="1.5708 1.5708 0" />
      <geometry>
        <mesh
          filename="meshes/visual_meshes/leg/innerShank_joint_visual.obj"/>
      </geometry>
      <material
        name="shank_material">
      </material>
    </visual>
    <visual name="innerShank_rod_visual">
      <origin
        xyz="0 0 0"
        rpy="1.5708 1.5708 0" />
      <geometry>
        <mesh
          filename="meshes/visual_meshes/leg/innerShank_rod_visual.obj"/>
      </geometry>
      <material
        name="shank_material">
      </material>
    </visual>
    <visual name="innerShank_paw_visual">
      <origin
        xyz="0 0 0"
        rpy="1.5708 1.5708 0" />
      <geometry>
        <mesh
          filename="meshes/visual_meshes/leg/innerShank_paw_visual.obj"/>
      </geometry>
      <material
        name="shank_material">
      </material>
    </visual>

    <collision name="innerShank_joint_collision">
      <origin
        xyz="0 0 0"
        rpy="1.5708 1.5708 0" />
      <geometry>
        <mesh
          filename="meshes/collision_meshes/leg/innerShank_joint_collision.obj"/>
      </geometry>
    </collision>
    <collision name="innerShank_rod_collision">
      <origin
        xyz="0 0 0"
        rpy="1.5708 1.5708 0" />
      <geometry>
        <mesh
          filename="meshes/collision_meshes/leg/innerShank_rod_collision.obj"/>
      </geometry>
    </collision>
    <collision name="innerShank_paw_collision">
      <origin
        xyz="0 0 0"
        rpy="1.5708 1.5708 0" />
      <geometry>
        <mesh
          filename="meshes/collision_meshes/leg/innerShank_paw_collision.obj"/>
      </geometry>
    </collision>
  </link>
  <joint
    name="FrontLeft_shank_inner_knee"
    type="revolute">
    <origin
      xyz="0 0.000750000000007855 -0.175000000000014"
      rpy="0 -0.156107447167547 0" />
    <parent
      link="FrontLeft_hip_inner" />
    <child
      link="FrontLeft_shank_inner" />
    <axis
      xyz="0 1 0" />
    <limit
      lower="-2.7504"
      upper="1.2296"
      effort="0"
      velocity="0" />
    <dynamics damping="0.0025" />
  </joint>
  <link name="FrontLeft_paw">
    <inertial>
      <origin
        xyz="-0.00016141 -2.5484E-07 0.0013973"
        rpy="0 0 0" />
      <mass
        value="0.02" />
      <inertia
        ixx="3.73E-06"
        ixy="-2.6396E-10"
        ixz="-2E-08"
        iyy="4.78E-06"
        iyz="-7.8092E-11"
        izz="6.37E-06" />
    </inertial>
  </link>
  <joint
    name="FrontLeft_paw"
    type="fixed">
    <origin
      xyz="-0.034316172849209 0 -0.318287120023731"
      rpy="0 -0.587745839939292 3.14159265358979" />
    <parent
      link="FrontLeft_shank_inner" />
    <child
      link="FrontLeft_paw" />
    <axis
      xyz="0 0 0" />
  </joint>
 
  <!-- Front Right Leg: -->
  <link name="FrontRight_motorHousing">
    <inertial>
      <origin
        xyz="0.092829 -0.02913 -0.00023828"
        rpy="0 0 0" />
      <mass
        value="1.4374" />
      <inertia
        ixx="0.00232895"
        ixy="-0.00418147"
        ixz="-3.194E-05"
        iyy="0.01861991"
        iyz="4.4E-06"
        izz="0.01948836" />
    </inertial>
    <visual name="MH_visual">
      <origin
        xyz="0.005 0 0"
        rpy="-1.5708 0 0" />
      <geometry>
        <mesh
          filename="meshes/visual_meshes/leg/MH_visual.obj"/>
      </geometry>
      <material
        name="housing_material">
      </material>
    </visual>

    <collision name="MH_collision">
      <origin
        xyz="0.005 0 0"
        rpy="-1.5708 0 0" />
      <geometry>
        <mesh
          filename="meshes/collision_meshes/leg/MH_collision.obj"/>
      </geometry>
    </collision>
  </link>
  <joint
    name="FrontRight_motorHousing_hipAduction_motor6"
    type="revolute">
    <origin
      xyz="0.143300000000001 -0.104999999999999 0"
      rpy="0 0 0" />
    <parent
      link="Body" />
    <child
      link="FrontRight_motorHousing" />
    <axis
      xyz="-1 0 0" />
    <limit
      lower="-1.57"
      upper="3.1416"
      effort="0"
      velocity="0" />
    <dynamics damping="0.0025" />
  </joint>
  <link name="FrontRight_hip_outer">
    <inertial>
      <origin
        xyz="0.00087111 0.0026375 -0.059532"
        rpy="0 0 0" />
      <mass
        value="0.0805" />
      <inertia
        ixx="0.00080743"
        ixy="-7E-08"
        ixz="-1.1E-05"
        iyy="0.00081318"
        iyz="4.71E-06"
        izz="8.42E-06" />
    </inertial>
    <visual name="outerHip_long_visual">
      <origin
        xyz="0 0 0"
        rpy="0 0 0" />
      <geometry>
        <mesh
          filename="meshes/visual_meshes/leg/outerHip_long_visual.obj"/>
      </geometry>
      <material
        name="hip_material">
      </material>
    </visual>
    <visual name="outerHip_shank_visual">
      <origin
        xyz="0 0 0"
        rpy="0 0 0" />
      <geometry>
        <mesh
          filename="meshes/visual_meshes/leg/outerHip_shank_visual.obj"/>
      </geometry>
      <material
        name="hip_material">
      </material>
    </visual>

    <collision name="outerHip_long_collision">
      <origin
        xyz="0 0 0"
        rpy="0 0 0" />
      <geometry>
        <mesh
          filename="meshes/collision_meshes/leg/outerHip_long_collision.obj"/>
      </geometry>
    </collision>
    <collision name="outerHip_shank_collision">
      <origin
        xyz="0 0 0"
        rpy="0 0 0" />
      <geometry>
        <mesh
          filename="meshes/collision_meshes/leg/outerHip_shank_collision.obj"/>
      </geometry>
    </collision>
  </link>
  <joint
    name="FrontRight_hip_outer_motor4"
    type="revolute">
    <origin
      xyz="0.141700000000001 -0.0594500000000023 1.13383701978259E-05"
      rpy="0 0 0" />
    <parent
      link="FrontRight_motorHousing" />
    <child
      link="FrontRight_hip_outer" />
    <axis
      xyz="0 1 0" />
    <limit
      lower="-3.8776"
      upper="1.2040" 
      effort="0"
      velocity="0" />
    <dynamics damping="0.0025" />
  </joint>
  <link name="FrontRight_shank_outer">
    <inertial>
      <origin
        xyz="0.0044745 -6.1929E-07 -0.16466"
        rpy="0 0 0" />
      <mass
        value="0.1992" />
      <inertia
        ixx="0.0081046"
        ixy="3E-08"
        ixz="-8.7E-05"
        iyy="0.00810896"
        iyz="-1.7E-06"
        izz="2.321E-05" />
    </inertial>
    <visual name="outerShank_joint_visual">
      <origin
        xyz="0 0 0"
        rpy="1.5708 1.5708 0" />
      <geometry>
        <mesh
          filename="meshes/visual_meshes/leg/outerShank_joint_visual.obj"/>
      </geometry>
      <material
        name="shank_material">
      </material>
    </visual>
    <visual name="outerShank_rod_visual">
      <origin
        xyz="0 0 0"
        rpy="1.5708 1.5708 0" />
      <geometry>
        <mesh
          filename="meshes/visual_meshes/leg/outerShank_rod_visual.obj"/>
      </geometry>
      <material
        name="shank_material">
      </material>
    </visual>
    <visual name="outerShank_paw_visual">
      <origin
        xyz="0 0 0"
        rpy="1.5708 1.5708 0" />
      <geometry>
        <mesh
          filename="meshes/visual_meshes/leg/outerShank_paw_visual.obj"/>
      </geometry>
      <material
        name="shank_material">
      </material>
    </visual>

    <collision name="outerShank_joint_collision">
      <origin
        xyz="0 0 0"
        rpy="1.5708 1.5708 0" />
      <geometry>
        <mesh
          filename="meshes/collision_meshes/leg/outerShank_joint_collision.obj"/>
      </geometry>
    </collision>
    <collision name="outerShank_rod_collision">
      <origin
        xyz="0 0 0"
        rpy="1.5708 1.5708 0" />
      <geometry>
        <mesh
          filename="meshes/collision_meshes/leg/outerShank_rod_collision.obj"/>
      </geometry>
    </collision>
    <collision name="outerShank_paw_collision">
      <origin
        xyz="0 0 0"
        rpy="1.5708 1.5708 0" />
      <geometry>
        <mesh
          filename="meshes/collision_meshes/leg/outerShank_paw_collision.obj"/>
      </geometry>
    </collision>
  </link>
  <joint
    name="FrontRight_shank_outer_knee"
    type="revolute">
    <origin
      xyz="0 -0.000750000000000334 -0.174999999999994"
      rpy="0 0.145529485228574 0" />
    <parent
      link="FrontRight_hip_outer" />
    <child
      link="FrontRight_shank_outer" />
    <axis
      xyz="0 1 0" />
    <limit
      lower="-1.2222"
      upper="2.6878"
      effort="0"
      velocity="0" />
    <dynamics damping="0.0025" />
  </joint>
  <link name="FrontRight_hip_inner">
    <inertial>
      <origin
        xyz="-0.00087097 0.0026333 -0.059284"
        rpy="0 0 0" />
      <mass
        value="0.081" />
      <inertia
        ixx="0.00080451"
        ixy="7E-08"
        ixz="1.098E-05"
        iyy="0.00081035"
        iyz="4.68E-06"
        izz="8.51E-06" />
    </inertial>
    <visual name="innerHip_long_visual">
      <origin
        xyz="0 0 0"
        rpy="0 0 0" />
      <geometry>
        <mesh
          filename="meshes/visual_meshes/leg/innerHip_long_visual.obj"/>
      </geometry>
      <material
        name="hip_material">
      </material>
    </visual>
    <visual name="innerHip_shank_visual">
      <origin
        xyz="0 0 0"
        rpy="0 0 0" />
      <geometry>
        <mesh
          filename="meshes/visual_meshes/leg/innerHip_shank_visual.obj"/>
      </geometry>
      <material
        name="hip_material">
      </material>
    </visual>

    <collision name="innerHip_long_collision">
      <origin
        xyz="0 0 0"
        rpy="0 0 0" />
      <geometry>
        <mesh
          filename="meshes/collision_meshes/leg/innerHip_long_collision.obj"/>
      </geometry>
    </collision>
    <collision name="innerHip_shank_collision">
      <origin
        xyz="0 0 0"
        rpy="0 0 0" />
      <geometry>
        <mesh
          filename="meshes/collision_meshes/leg/innerHip_shank_collision.obj"/>
      </geometry>
    </collision>
  </link>
  <joint
    name="FrontRight_hip_inner_motor5"
    type="revolute">
    <origin
      xyz="0.0517000000000003 -0.0594500000000019 1.13383701956029E-05"
      rpy="0 0 0" />
    <parent
      link="FrontRight_motorHousing" />
    <child
      link="FrontRight_hip_inner" />
    <axis
      xyz="0 1 0" />
    <limit
      lower="-1.2013"
      upper="3.8803"
      effort="0"
      velocity="0" />
    <dynamics damping="0.0025" />
  </joint>
  <link name="FrontRight_shank_inner">
    <inertial>
      <origin
        xyz="-0.018257 -5.8199E-07 -0.18193"
        rpy="0 0 0" />
      <mass
        value="0.1992" />
      <inertia
        ixx="0.00799515"
        ixy="-1.3E-07"
        ixz="0.00072855"
        iyy="0.00807089"
        iyz="-1.55E-06"
        izz="9.64E-05" />
    </inertial>
    <visual name="innerShank_joint_visual">
      <origin
        xyz="0 0 0"
        rpy="1.5708 1.5708 0" />
      <geometry>
        <mesh
          filename="meshes/visual_meshes/leg/innerShank_joint_visual.obj"/>
      </geometry>
      <material
        name="shank_material">
      </material>
    </visual>
    <visual name="innerShank_rod_visual">
      <origin
        xyz="0 0 0"
        rpy="1.5708 1.5708 0" />
      <geometry>
        <mesh
          filename="meshes/visual_meshes/leg/innerShank_rod_visual.obj"/>
      </geometry>
      <material
        name="shank_material">
      </material>
    </visual>
    <visual name="innerShank_paw_visual">
      <origin
        xyz="0 0 0"
        rpy="1.5708 1.5708 0" />
      <geometry>
        <mesh
          filename="meshes/visual_meshes/leg/innerShank_paw_visual.obj"/>
      </geometry>
      <material
        name="shank_material">
      </material>
    </visual>

    <collision name="innerShank_joint_collision">
      <origin
        xyz="0 0 0"
        rpy="1.5708 1.5708 0" />
      <geometry>
        <mesh
          filename="meshes/collision_meshes/leg/innerShank_joint_collision.obj"/>
      </geometry>
    </collision>
    <collision name="innerShank_rod_collision">
      <origin
        xyz="0 0 0"
        rpy="1.5708 1.5708 0" />
      <geometry>
        <mesh
          filename="meshes/collision_meshes/leg/innerShank_rod_collision.obj"/>
      </geometry>
    </collision>
    <collision name="innerShank_paw_collision">
      <origin
        xyz="0 0 0"
        rpy="1.5708 1.5708 0" />
      <geometry>
        <mesh
          filename="meshes/collision_meshes/leg/innerShank_paw_collision.obj"/>
      </geometry>
    </collision>
  </link>
  <joint
    name="FrontRight_shank_inner_knee"
    type="revolute">
    <origin
      xyz="0 -0.000749999999992201 -0.174999999999991"
      rpy="0 -0.156107447167536 0" />
    <parent
      link="FrontRight_hip_inner" />
    <child
      link="FrontRight_shank_inner" />
    <axis
      xyz="0 1 0" />
    <limit
      lower="-2.7504"
      upper="1.2296"
      effort="0"
      velocity="0" />
    <dynamics damping="0.0025" />
  </joint>
  <link name="FrontRight_paw">
    <inertial>
      <origin
        xyz="-0.00016141 -2.5484E-07 0.0013973"
        rpy="0 0 0" />
      <mass
        value="0.02" />
      <inertia
        ixx="3.73E-06"
        ixy="0"
        ixz="-2E-08"
        iyy="4.78E-06"
        iyz="0"
        izz="6.37E-06" />
    </inertial>
  </link>
  <joint
    name="FrontRight_paw"
    type="fixed">
    <origin
      xyz="-0.0343161728492139 0 -0.318287120023735"
      rpy="0 -0.587745839939292 3.14159265358979" />
    <parent
      link="FrontRight_shank_inner" />
    <child
      link="FrontRight_paw" />
    <axis
      xyz="0 0 0" />
  </joint>
  
  <!-- Back Left Leg: -->
  <link name="BackLeft_motorHousing">
    <inertial>
      <origin
        xyz="-0.092829 0.02913 -0.00023828"
        rpy="0 0 0" />
      <mass
        value="1.437" />
      <inertia
        ixx="0.00232895"
        ixy="-0.00418147"
        ixz="3.194E-05"
        iyy="0.01861991"
        iyz="-4.4E-06"
        izz="0.01948836" />
    </inertial>
    <visual name="MH_visual">
      <origin
        xyz="-0.005 0 0"
        rpy="-1.5708 0 3.14159" />
      <geometry>
        <mesh
          filename="meshes/visual_meshes/leg/MH_visual.obj"/>
      </geometry>
      <material
        name="housing_material">
      </material>
    </visual>

    <collision name="MH_collision">
      <origin
        xyz="-0.005 0 0"
        rpy="-1.5708 0 3.14159" />
      <geometry>
        <mesh
          filename="meshes/collision_meshes/leg/MH_collision.obj"/>
      </geometry>
    </collision> 
  </link>
  <joint
    name="BackLeft_motorHousing_hipAduction_motor9"
    type="revolute">
    <origin
      xyz="-0.143300000000002 0.149999999999995 0"
      rpy="0 0 0" />
    <parent
      link="Body" />
    <child
      link="BackLeft_motorHousing" />
    <axis
      xyz="1 0 0" />
    <limit
      lower="-1.57"
      upper="3.1416"
      effort="0"
      velocity="0" />
    <dynamics damping="0.0025" />
  </joint>
  <link name="BackLeft_hip_outer">
    <inertial>
      <origin
        xyz="-0.00087111 -0.0026375 -0.059532"
        rpy="0 0 0" />
      <mass
        value="0.0805" />
      <inertia
        ixx="0.00080743"
        ixy="-7E-08"
        ixz="1.1E-05"
        iyy="0.00081318"
        iyz="-4.71E-06"
        izz="8.42E-06" />
    </inertial>
    <visual name="outerHip_long_visual">
      <origin
        xyz="0 0 0"
        rpy="0 0 3.14159" />
      <geometry>
        <mesh
          filename="meshes/visual_meshes/leg/outerHip_long_visual.obj"/>
      </geometry>
      <material
        name="hip_material">
      </material>
    </visual>
    <visual name="outerHip_shank_visual">
      <origin
        xyz="0 0 0"
        rpy="0 0 3.14159" />
      <geometry>
        <mesh
          filename="meshes/visual_meshes/leg/outerHip_shank_visual.obj"/>
      </geometry>
      <material
        name="hip_material">
      </material>
    </visual>

    <collision name="outerHip_long_collision">
      <origin
        xyz="0 0 0"
        rpy="0 0 3.14159" />
      <geometry>
        <mesh
          filename="meshes/collision_meshes/leg/outerHip_long_collision.obj"/>
      </geometry>
    </collision>
    <collision name="outerHip_shank_collision">
      <origin
        xyz="0 0 0"
        rpy="0 0 3.14159" />
      <geometry>
        <mesh
          filename="meshes/collision_meshes/leg/outerHip_shank_collision.obj"/>
      </geometry>
    </collision>
  </link>
  <joint
    name="BackLeft_hip_outer_motor7"
    type="revolute">
    <origin
      xyz="-0.141699999999998 0.059450000000001 1.13383699833258E-05"
      rpy="0 0 0" />
    <parent
      link="BackLeft_motorHousing" />
    <child
      link="BackLeft_hip_outer" />
    <axis
      xyz="0 -1 0" />
    <limit
      lower="-3.8776"
      upper="1.2040"
      effort="0"
      velocity="0" />
    <dynamics damping="0.0025" />
  </joint>
  <link name="BackLeft_shank_outer">
    <inertial>
      <origin
        xyz="-0.0044745 6.2096E-07 -0.16466"
        rpy="0 0 0" />
      <mass
        value="0.1992" />
      <inertia
        ixx="0.0081046"
        ixy="3E-08"
        ixz="8.7E-05"
        iyy="0.00810896"
        iyz="1.7E-06"
        izz="2.321E-05" />
    </inertial>
    <visual name="outerShank_joint_visual">
      <origin
        xyz="0 0 0"
        rpy="-1.5708 1.5708 0" />
      <geometry>
        <mesh
          filename="meshes/visual_meshes/leg/outerShank_joint_visual.obj"/>
      </geometry>
      <material
        name="shank_material">
      </material>
    </visual>
    <visual name="outerShank_rod_visual">
      <origin
        xyz="0 0 0"
        rpy="-1.5708 1.5708 0" />
      <geometry>
        <mesh
          filename="meshes/visual_meshes/leg/outerShank_rod_visual.obj"/>
      </geometry>
      <material
        name="shank_material">
      </material>
    </visual>
    <visual name="outerShank_paw_visual">
      <origin
        xyz="0 0 0"
        rpy="-1.5708 1.5708 0" />
      <geometry>
        <mesh
          filename="meshes/visual_meshes/leg/outerShank_paw_visual.obj"/>
      </geometry>
      <material
        name="shank_material">
      </material>
    </visual>

    <collision name="outerShank_joint_collision">
      <origin
        xyz="0 0 0"
        rpy="-1.5708 1.5708 0" />
      <geometry>
        <mesh
          filename="meshes/collision_meshes/leg/outerShank_joint_collision.obj"/>
      </geometry>
    </collision>
    <collision name="outerShank_rod_collision">
      <origin
        xyz="0 0 0"
        rpy="-1.5708 1.5708 0" />
      <geometry>
        <mesh
          filename="meshes/collision_meshes/leg/outerShank_rod_collision.obj"/>
      </geometry>
    </collision>
    <collision name="outerShank_paw_collision">
      <origin
        xyz="0 0 0"
        rpy="-1.5708 1.5708 0" />
      <geometry>
        <mesh
          filename="meshes/collision_meshes/leg/outerShank_paw_collision.obj"/>
      </geometry>
    </collision>
  </link>
  <joint
    name="BackLeft_shank_outer_knee"
    type="revolute">
    <origin
      xyz="0 0.000749999999989648 -0.174999999999787"
      rpy="0 -0.145529485231085 0" />
    <parent
      link="BackLeft_hip_outer" />
    <child
      link="BackLeft_shank_outer" />
    <axis
      xyz="0 1 0" />
    <limit
      lower="-2.6878"
      upper="1.2222"
      effort="0"
      velocity="0" />
    <dynamics damping="0.0025" />
  </joint>
  <link name="BackLeft_hip_inner">
    <inertial>
      <origin
        xyz="0.00087097 -0.0026333 -0.059284"
        rpy="0 0 0" />
      <mass
        value="0.081" />
      <inertia
        ixx="0.00080451"
        ixy="7E-08"
        ixz="-1.097E-05"
        iyy="0.00081035"
        iyz="-4.68E-06"
        izz="8.51E-06" />
    </inertial>
    <visual name="innerHip_long_visual">
      <origin
        xyz="0 0 0"
        rpy="0 0 3.14159" />
      <geometry>
        <mesh
          filename="meshes/visual_meshes/leg/innerHip_long_visual.obj"/>
      </geometry>
      <material
        name="hip_material">
      </material>
    </visual>
    <visual name="innerHip_shank_visual">
      <origin
        xyz="0 0 0"
        rpy="0 0 3.14159" />
      <geometry>
        <mesh
          filename="meshes/visual_meshes/leg/innerHip_shank_visual.obj"/>
      </geometry>
      <material
        name="hip_material">
      </material>
    </visual>

    <collision name="innerHip_long_collision">
      <origin
        xyz="0 0 0"
        rpy="0 0 3.14159" />
      <geometry>
        <mesh
          filename="meshes/collision_meshes/leg/innerHip_long_collision.obj"/>
      </geometry>
    </collision>
    <collision name="innerHip_shank_collision">
      <origin
        xyz="0 0 0"
        rpy="0 0 3.14159" />
      <geometry>
        <mesh
          filename="meshes/collision_meshes/leg/innerHip_shank_collision.obj"/>
      </geometry>
    </collision>
  </link>
  <joint
    name="BackLeft_hip_inner_motor8"
    type="revolute">
    <origin
      xyz="-0.0516999999999978 0.0594500000000004 1.13383700547322E-05"
      rpy="0 0 0" />
    <parent
      link="BackLeft_motorHousing" />
    <child
      link="BackLeft_hip_inner" />
    <axis
      xyz="0 -1 0" />
    <limit
      lower="-1.2013"
      upper="3.8803"
      effort="0"
      velocity="0" />
    <dynamics damping="0.0025" />
  </joint>
  <link name="BackLeft_shank_inner">
    <inertial>
      <origin
        xyz="0.018257 5.8939E-07 -0.18193"
        rpy="0 0 0" />
      <mass
        value="0.1993" />
      <inertia
        ixx="0.00799515"
        ixy="-1.3E-07"
        ixz="-0.00072855"
        iyy="0.00807089"
        iyz="1.55E-06"
        izz="9.64E-05" />
    </inertial>
    <visual name="innerShank_joint_visual">
      <origin
        xyz="0 0 0"
        rpy="-1.5708 1.5708 0" />
      <geometry>
        <mesh
          filename="meshes/visual_meshes/leg/innerShank_joint_visual.obj"/>
      </geometry>
      <material
        name="shank_material">
      </material>
    </visual>
    <visual name="innerShank_rod_visual">
      <origin
        xyz="0 0 0"
        rpy="-1.5708 1.5708 0" />
      <geometry>
        <mesh
          filename="meshes/visual_meshes/leg/innerShank_rod_visual.obj"/>
      </geometry>
      <material
        name="shank_material">
      </material>
    </visual>
    <visual name="innerShank_paw_visual">
      <origin
        xyz="0 0 0"
        rpy="-1.5708 1.5708 0" />
      <geometry>
        <mesh
          filename="meshes/visual_meshes/leg/innerShank_paw_visual.obj"/>
      </geometry>
      <material
        name="shank_material">
      </material>
    </visual>

    <collision name="innerShank_joint_collision">
      <origin
        xyz="0 0 0"
        rpy="-1.5708 1.5708 0" />
      <geometry>
        <mesh
          filename="meshes/collision_meshes/leg/innerShank_joint_collision.obj"/>
      </geometry>
    </collision>
    <collision name="innerShank_rod_collision">
      <origin
        xyz="0 0 0"
        rpy="-1.5708 1.5708 0" />
      <geometry>
        <mesh
          filename="meshes/collision_meshes/leg/innerShank_rod_collision.obj"/>
      </geometry>
    </collision>
    <collision name="innerShank_paw_collision">
      <origin
        xyz="0 0 0"
        rpy="-1.5708 1.5708 0" />
      <geometry>
        <mesh
          filename="meshes/collision_meshes/leg/innerShank_paw_collision.obj"/>
      </geometry>
    </collision>
  </link>
  <joint
    name="BackLeft_shank_inner_knee"
    type="revolute">
    <origin
      xyz="0 0.000749999999984485 -0.174999999999858"
      rpy="0 0.156107447167218 0" />
    <parent
      link="BackLeft_hip_inner" />
    <child
      link="BackLeft_shank_inner" />
    <axis
      xyz="0 1 0" />
    <limit
      lower="-1.2296"
      upper="2.7504"
      effort="0"
      velocity="0" />
    <dynamics damping="0.0025" />
  </joint>
  <link name="BackLeft_paw">
    <inertial>
      <origin
        xyz="0.00016141 2.5484E-07 0.0013973"
        rpy="0 0 0" />
      <mass
        value="0.02" />
      <inertia
        ixx="1.236E-05"
        ixy="0"
        ixz="5E-08"
        iyy="1.587E-05"
        iyz="0"
        izz="2.129E-05" />
    </inertial>
  </link>
  <joint
    name="BackLeft_paw"
    type="fixed">
    <origin
      xyz="0.0343161728493504 0 -0.318287120023714"
      rpy="0 0.587745839939292 -3.14159265358976" />
    <parent
      link="BackLeft_shank_inner" />
    <child
      link="BackLeft_paw" />
    <axis
      xyz="0 0 0" />
  </joint>
 
  <!-- Back Right Leg: -->
  <link name="BackRight_motorHousing">
    <inertial>
      <origin
        xyz="-0.092829 -0.02913 0.00023828"
        rpy="0 0 0" />
      <mass
        value="1.437" />
      <inertia
        ixx="0.00232895"
        ixy="0.00418147"
        ixz="-3.194E-05"
        iyy="0.01861991"
        iyz="-4.4E-06"
        izz="0.01948836" />
    </inertial>
    <visual name="MH_visual">
      <origin
        xyz="-0.005 0 0"
        rpy="1.5708 0 3.14159" />
      <geometry>
        <mesh
          filename="meshes/visual_meshes/leg/MH_visual.obj"/>
      </geometry>
      <material
        name="housing_material">
      </material>
    </visual> 

    <collision name="MH_collision">
      <origin
        xyz="-0.005 0 0"
        rpy="1.5708 0 3.14159" />
      <geometry>
        <mesh
          filename="meshes/collision_meshes/leg/MH_collision.obj"/>
      </geometry>
    </collision> 
  </link>
  <joint
    name="BackRight_motorHousing_hipAduction_motor12"
    type="revolute">
    <origin
      xyz="-0.1433 -0.150000000000002 0"
      rpy="0 0 0" />
    <parent
      link="Body" />
    <child
      link="BackRight_motorHousing" />
    <axis
      xyz="1 0 0" />
    <limit
      lower="-3.1416"
      upper="1.57"
      effort="0"
      velocity="0" />
    <dynamics damping="0.0025" />
  </joint>
  <link name="BackRight_hip_outer">
    <inertial>
      <origin
        xyz="-0.00087097 0.0026333 -0.059284"
        rpy="0 0 0" />
      <mass
        value="0.081" />
      <inertia
        ixx="0.00080451"
        ixy="7E-08"
        ixz="1.098E-05"
        iyy="0.00081035"
        iyz="4.68E-06"
        izz="8.51E-06" />
    </inertial>
    <visual name="outerHip_long_visual">
      <origin
        xyz="0 0 0"
        rpy="0 0 3.14159" />
      <geometry>
        <mesh
          filename="meshes/visual_meshes/leg/outerHip_long_visual.obj"/>
      </geometry>
      <material
        name="hip_material">
      </material>
    </visual>
    <visual name="outerHip_shank_visual">
      <origin
        xyz="0 0 0"
        rpy="0 0 3.14159" />
      <geometry>
        <mesh
          filename="meshes/visual_meshes/leg/outerHip_shank_visual.obj"/>
      </geometry>
      <material
        name="hip_material">
      </material>
    </visual>

    <collision name="outerHip_long_collision">
      <origin
        xyz="0 0 0"
        rpy="0 0 3.14159" />
      <geometry>
        <mesh
          filename="meshes/collision_meshes/leg/outerHip_long_collision.obj"/>
      </geometry>
    </collision>
    <collision name="outerHip_shank_collision">
      <origin
        xyz="0 0 0"
        rpy="0 0 3.14159" />
      <geometry>
        <mesh
          filename="meshes/collision_meshes/leg/outerHip_shank_collision.obj"/>
      </geometry>
    </collision>
  </link>
  <joint
    name="BackRight_hip_outer_motor10"
    type="revolute">
    <origin
      xyz="-0.1417 -0.0594500000000014 -1.13383706822422E-05"
      rpy="0 0 0" />
    <parent
      link="BackRight_motorHousing" />
    <child
      link="BackRight_hip_outer" />
    <axis
      xyz="0 1 0" />
    <limit
      lower="-1.2040"
      upper="3.8776"
      effort="0"
      velocity="0" />
    <dynamics damping="0.0025" />
  </joint>
  <link name="BackRight_shank_outer">
    <inertial>
      <origin
        xyz="-0.0044745 6.1738E-07 -0.16466"
        rpy="0 0 0" />
      <mass
        value="0.1992" />
      <inertia
        ixx="0.0081046"
        ixy="3E-08"
        ixz="8.7E-05"
        iyy="0.00810896"
        iyz="1.7E-06"
        izz="2.321E-05" />
    </inertial>
    <visual name="outerShank_joint_visual">
      <origin
        xyz="0 0 0"
        rpy="-1.5708 1.5708 0" />
      <geometry>
        <mesh
          filename="meshes/visual_meshes/leg/outerShank_joint_visual.obj"/>
      </geometry>
      <material
        name="shank_material">
      </material>
    </visual>
    <visual name="outerShank_rod_visual">
      <origin
        xyz="0 0 0"
        rpy="-1.5708 1.5708 0" />
      <geometry>
        <mesh
          filename="meshes/visual_meshes/leg/outerShank_rod_visual.obj"/>
      </geometry>
      <material
        name="shank_material">
      </material>
    </visual>
    <visual name="outerShank_paw_visual">
      <origin
        xyz="0 0 0"
        rpy="-1.5708 1.5708 0" />
      <geometry>
        <mesh
          filename="meshes/visual_meshes/leg/outerShank_paw_visual.obj"/>
      </geometry>
      <material
        name="shank_material">
      </material>
    </visual>

    <collision name="outerShank_joint_collision">
      <origin
        xyz="0 0 0"
        rpy="-1.5708 1.5708 0" />
      <geometry>
        <mesh
          filename="meshes/collision_meshes/leg/outerShank_joint_collision.obj"/>
      </geometry>
    </collision>
    <collision name="outerShank_rod_collision">
      <origin
        xyz="0 0 0"
        rpy="-1.5708 1.5708 0" />
      <geometry>
        <mesh
          filename="meshes/collision_meshes/leg/outerShank_rod_collision.obj"/>
      </geometry>
    </collision>
    <collision name="outerShank_paw_collision">
      <origin
        xyz="0 0 0"
        rpy="-1.5708 1.5708 0" />
      <geometry>
        <mesh
          filename="meshes/collision_meshes/leg/outerShank_paw_collision.obj"/>
      </geometry>
    </collision>
  </link>
  <joint
    name="BackRight_shank_outer_knee"
    type="revolute">
    <origin
      xyz="0 -0.000749999999264783 -0.174999999999897"
      rpy="0 -0.145529485225738 0" />
    <parent
      link="BackRight_hip_outer" />
    <child
      link="BackRight_shank_outer" />
    <axis
      xyz="0 1 0" />
    <limit
      lower="-2.6878"
      upper="1.2222"
      effort="0"
      velocity="0" />
    <dynamics damping="0.0025" />
  </joint>
  <link name="BackRight_hip_inner">
    <inertial>
      <origin
        xyz="0.00087111 0.0026375 -0.059532"
        rpy="0 0 0" />
      <mass
        value="0.0805" />
      <inertia
        ixx="0.00080743"
        ixy="-7E-08"
        ixz="-1.1E-05"
        iyy="0.00081318"
        iyz="4.71E-06"
        izz="8.42E-06" />
    </inertial>
    <visual name="innerHip_long_visual">
      <origin
        xyz="0 0 0"
        rpy="0 0 3.14159" />
      <geometry>
        <mesh
          filename="meshes/visual_meshes/leg/innerHip_long_visual.obj"/>
      </geometry>
      <material
        name="hip_material">
      </material>
    </visual>
    <visual name="innerHip_shank_visual">
      <origin
        xyz="0 0 0"
        rpy="0 0 3.14159" />
      <geometry>
        <mesh
          filename="meshes/visual_meshes/leg/innerHip_shank_visual.obj"/>
      </geometry>
      <material
        name="hip_material">
      </material>
    </visual>

    <collision name="innerHip_long_collision">
      <origin
        xyz="0 0 0"
        rpy="0 0 3.14159" />
      <geometry>
        <mesh
          filename="meshes/collision_meshes/leg/innerHip_long_collision.obj"/>
      </geometry>
    </collision>
    <collision name="innerHip_shank_collision">
      <origin
        xyz="0 0 0"
        rpy="0 0 3.14159" />
      <geometry>
        <mesh
          filename="meshes/collision_meshes/leg/innerHip_shank_collision.obj"/>
      </geometry>
    </collision>
  </link>
  <joint
    name="BackRight_hip_inner_motor11"
    type="revolute">
    <origin
      xyz="-0.0517000000000002 -0.0594500000000022 -1.1338370431546E-05"
      rpy="0 0 0" />
    <parent
      link="BackRight_motorHousing" />
    <child
      link="BackRight_hip_inner" />
    <axis
      xyz="0 1 0" />
    <limit
      lower="-3.8803"
      upper="1.2013"
      effort="0"
      velocity="0" />
    <dynamics damping="0.0025" />
  </joint>
  <link name="BackRight_shank_inner">
    <inertial>
      <origin
        xyz="0.018257 5.8084E-07 -0.18193"
        rpy="0 0 0" />
      <mass
        value="0.1993" />
      <inertia
        ixx="0.00799515"
        ixy="-1.3E-07"
        ixz="-0.00072855"
        iyy="0.00807089"
        iyz="1.55E-06"
        izz="9.64E-05" />
    </inertial>
    <visual name="innerShank_joint_visual">
      <origin
        xyz="0 0 0"
        rpy="-1.5708 1.5708 0" />
      <geometry>
        <mesh
          filename="meshes/visual_meshes/leg/innerShank_joint_visual.obj"/>
      </geometry>
      <material
        name="shank_material">
      </material>
    </visual>
    <visual name="innerShank_rod_visual">
      <origin
        xyz="0 0 0"
        rpy="-1.5708 1.5708 0" />
      <geometry>
        <mesh
          filename="meshes/visual_meshes/leg/innerShank_rod_visual.obj"/>
      </geometry>
      <material
        name="shank_material">
      </material>
    </visual>
    <visual name="innerShank_paw_visual">
      <origin
        xyz="0 0 0"
        rpy="-1.5708 1.5708 0" />
      <geometry>
        <mesh
          filename="meshes/visual_meshes/leg/innerShank_paw_visual.obj"/>
      </geometry>
      <material
        name="shank_material">
      </material>
    </visual>

    <collision name="innerShank_joint_collision">
      <origin
        xyz="0 0 0"
        rpy="-1.5708 1.5708 0" />
      <geometry>
        <mesh
          filename="meshes/collision_meshes/leg/innerShank_joint_collision.obj"/>
      </geometry>
    </collision>
    <collision name="innerShank_rod_collision">
      <origin
        xyz="0 0 0"
        rpy="-1.5708 1.5708 0" />
      <geometry>
        <mesh
          filename="meshes/collision_meshes/leg/innerShank_rod_collision.obj"/>
      </geometry>
    </collision>
    <collision name="innerShank_paw_collision">
      <origin
        xyz="0 0 0"
        rpy="-1.5708 1.5708 0" />
      <geometry>
        <mesh
          filename="meshes/collision_meshes/leg/innerShank_paw_collision.obj"/>
      </geometry>
    </collision>
  </link>
  <joint
    name="BackRight_shank_inner_knee"
    type="revolute">
    <origin
      xyz="0 -0.000749999999271611 -0.174999999999955"
      rpy="0 0.156107447164923 0" />
    <parent
      link="BackRight_hip_inner" />
    <child
      link="BackRight_shank_inner" />
    <axis
      xyz="0 1 0" />
    <limit
      lower="-1.2296"
      upper="2.7504"
      effort="0"
      velocity="0" />
    <dynamics damping="0.0025" />
  </joint>
  <link name="BackRight_paw">
    <inertial>
      <origin
        xyz="0.00016141 2.5484E-07 0.0013973"
        rpy="0 0 0" />
      <mass
        value="0.02" />
      <inertia
        ixx="1.245E-05"
        ixy="0"
        ixz="6E-08"
        iyy="1.597E-05"
        iyz="0"
        izz="2.129E-05" />
    </inertial>
  </link>
  <joint
    name="BackRight_paw"
    type="fixed">
    <origin
      xyz="0.0343161728494181 0 -0.318287120023818"
      rpy="0 0.58774583993929 3.14159265358979" />
    <parent
      link="BackRight_shank_inner" />
    <child
      link="BackRight_paw" />
    <axis
      xyz="0 0 0" />
  </joint>


</robot>